Workbook

Sheet todayssatellite
A1: Time | B1: Text | C1: Length | D1: Number | E1: Rocket_type | F1: Rocket_number | G1: for_search | H1: Updated_date | I1: Update_info | J1: memo
A2: 01/01 07:00:00 | B2: 【今日の人工衛星】1/1 1990年：JCSAT-2 日本のJSAT(現・スカパーJSAT)保有の通信衛星。タイタンIIIロケットで打上、東経154度からサービスを提供。現在は寿命が切れている。 | C2: =LEN(B2) -> 97 | D2: n010101d | E2: {=_xlfn.IFS(IFERROR(FIND("M-3SII",B2),-1)>0,"J_M3S2",IFERROR(FIND("M-V",B2),-1)>0,"J_M5",IFERROR(FIND("M-4S",B2),-1)>0,"J_M4S",IFERROR(FIND("M-3C",B2),-1)>0,"J_M3C",IFERROR(FIND("M-3S",B2),-1)>0,"J_M3S",IFERROR(FIND("M-3H",B2),-1)>0,"J_M3H",IFERROR(FIND("H-IIA",B2),-1)>0,"J_H2A",IFERROR(FIND("H-IIB",B2),-1)>0,"J_H2B",IFERROR(FIND("H-II",B2),-1)>0,"J_H2",IFERROR(FIND("H-I",B2),-1)>0,"J_H1",IFERROR(FIND("N-II",B2),-1)>0,"J_N2",IFERROR(FIND("N-I",B2),-1)>0,"J_N1",IFERROR(FIND("イプシロン",B2),-1)>0,"J_E",TRUE,"")} | G2: =IF(E2<>"",E2&"_"&F2,"")
A3: 01/02 07:00:00 | B3: 【今日の人工衛星】1/2 1959年：ルナ1号 旧ソ連の月探査機。旧ソ連は失敗した打上に番号を振らないため、月を目指した探査機としては4機目。月着陸には失敗したが人類初の人工惑星となった。 | C3: =LEN(B3) -> 94 | D3: n010201d | E3: {=_xlfn.IFS(IFERROR(FIND("M-3SII",B3),-1)>0,"J_M3S2",IFERROR(FIND("M-V",B3),-1)>0,"J_M5",IFERROR(FIND("M-4S",B3),-1)>0,"J_M4S",IFERROR(FIND("M-3C",B3),-1)>0,"J_M3C",IFERROR(FIND("M-3S",B3),-1)>0,"J_M3S",IFERROR(FIND("M-3H",B3),-1)>0,"J_M3H",IFERROR(FIND("H-IIA",B3),-1)>0,"J_H2A",IFERROR(FIND("H-IIB",B3),-1)>0,"J_H2B",IFERROR(FIND("H-II",B3),-1)>0,"J_H2",IFERROR(FIND("H-I",B3),-1)>0,"J_H1",IFERROR(FIND("N-II",B3),-1)>0,"J_N2",IFERROR(FIND("N-I",B3),-1)>0,"J_N1",IFERROR(FIND("イプシロン",B3),-1)>0,"J_E",TRUE,"")} | G3: =IF(E3<>"",E3&"_"&F3,"")
A4: 01/03 07:00:00 | B4: 【今日の人工衛星】1/3 1999年：マーズ・ポーラー・ランダー アメリカの火星探査機。火星の近傍までは無事に到着したものの、通信が途絶え、行方不明となった。現在も探査機の跡は見つかっていない | C4: =LEN(B4) -> 96 | D4: n010301d | E4: {=_xlfn.IFS(IFERROR(FIND("M-3SII",B4),-1)>0,"J_M3S2",IFERROR(FIND("M-V",B4),-1)>0,"J_M5",IFERROR(FIND("M-4S",B4),-1)>0,"J_M4S",IFERROR(FIND("M-3C",B4),-1)>0,"J_M3C",IFERROR(FIND("M-3S",B4),-1)>0,"J_M3S",IFERROR(FIND("M-3H",B4),-1)>0,"J_M3H",IFERROR(FIND("H-IIA",B4),-1)>0,"J_H2A",IFERROR(FIND("H-IIB",B4),-1)>0,"J_H2B",IFERROR(FIND("H-II",B4),-1)>0,"J_H2",IFERROR(FIND("H-I",B4),-1)>0,"J_H1",IFERROR(FIND("N-II",B4),-1)>0,"J_N2",IFERROR(FIND("N-I",B4),-1)>0,"J_N1",IFERROR(FIND("イプシロン",B4),-1)>0,"J_E",TRUE,"")} | G4: =IF(E4<>"",E4&"_"&F4,"")
A5: 01/04 07:00:00 | B5: 【今日の人工衛星】1/4 1963年：スプートニク25号 旧ソ連の月探査機。世界初の月軟着陸を目指し着陸機を搭載。月面の写真を撮影する予定だったが、地球周回軌道からの脱出に失敗、大気圏に再突入した。 | C5: =LEN(B5) -> 99 | D5: n010401d | E5: {=_xlfn.IFS(IFERROR(FIND("M-3SII",B5),-1)>0,"J_M3S2",IFERROR(FIND("M-V",B5),-1)>0,"J_M5",IFERROR(FIND("M-4S",B5),-1)>0,"J_M4S",IFERROR(FIND("M-3C",B5),-1)>0,"J_M3C",IFERROR(FIND("M-3S",B5),-1)>0,"J_M3S",IFERROR(FIND("M-3H",B5),-1)>0,"J_M3H",IFERROR(FIND("H-IIA",B5),-1)>0,"J_H2A",IFERROR(FIND("H-IIB",B5),-1)>0,"J_H2B",IFERROR(FIND("H-II",B5),-1)>0,"J_H2",IFERROR(FIND("H-I",B5),-1)>0,"J_H1",IFERROR(FIND("N-II",B5),-1)>0,"J_N2",IFERROR(FIND("N-I",B5),-1)>0,"J_N1",IFERROR(FIND("イプシロン",B5),-1)>0,"J_E",TRUE,"")} | G5: =IF(E5<>"",E5&"_"&F5,"")
A6: 01/05 07:00:00 | B6: 【今日の人工衛星】1/5 1969年：ベネラ5号 旧ソ連の金星探査機。ベネラ4号の観測結果を踏まえ、大気の測定がより精密に出来るようにされていた。 | C6: =LEN(B6) -> 73 | D6: n010501d | E6: {=_xlfn.IFS(IFERROR(FIND("M-3SII",B6),-1)>0,"J_M3S2",IFERROR(FIND("M-V",B6),-1)>0,"J_M5",IFERROR(FIND("M-4S",B6),-1)>0,"J_M4S",IFERROR(FIND("M-3C",B6),-1)>0,"J_M3C",IFERROR(FIND("M-3S",B6),-1)>0,"J_M3S",IFERROR(FIND("M-3H",B6),-1)>0,"J_M3H",IFERROR(FIND("H-IIA",B6),-1)>0,"J_H2A",IFERROR(FIND("H-IIB",B6),-1)>0,"J_H2B",IFERROR(FIND("H-II",B6),-1)>0,"J_H2",IFERROR(FIND("H-I",B6),-1)>0,"J_H1",IFERROR(FIND("N-II",B6),-1)>0,"J_N2",IFERROR(FIND("N-I",B6),-1)>0,"J_N1",IFERROR(FIND("イプシロン",B6),-1)>0,"J_E",TRUE,"")} | G6: =IF(E6<>"",E6&"_"&F6,"")
A7: 01/06 07:00:00 | B7: 【今日の人工衛星】1/6 2003年：Coriolis アメリカの打ち上げた衛星。海面を吹く風を観測するWindSatと、太陽からの物質の放出を観測するSMEIを搭載 | C7: =LEN(B7) -> 83 | D7: n010601d | E7: {=_xlfn.IFS(IFERROR(FIND("M-3SII",B7),-1)>0,"J_M3S2",IFERROR(FIND("M-V",B7),-1)>0,"J_M5",IFERROR(FIND("M-4S",B7),-1)>0,"J_M4S",IFERROR(FIND("M-3C",B7),-1)>0,"J_M3C",IFERROR(FIND("M-3S",B7),-1)>0,"J_M3S",IFERROR(FIND("M-3H",B7),-1)>0,"J_M3H",IFERROR(FIND("H-IIA",B7),-1)>0,"J_H2A",IFERROR(FIND("H-IIB",B7),-1)>0,"J_H2B",IFERROR(FIND("H-II",B7),-1)>0,"J_H2",IFERROR(FIND("H-I",B7),-1)>0,"J_H1",IFERROR(FIND("N-II",B7),-1)>0,"J_N2",IFERROR(FIND("N-I",B7),-1)>0,"J_N1",IFERROR(FIND("イプシロン",B7),-1)>0,"J_E",TRUE,"")} | G7: =IF(E7<>"",E7&"_"&F7,"")
A8: 01/07 07:00:00 | B8: 【今日の人工衛星】1/7 1998年：ルナ・プロスペクター アメリカの月探査機。クレメンタインの観測が示唆した月面の氷の存在の検証が重要な目的。中性子線分光計により水素の存在が確認され、水の存在の示唆が得られた | C8: =LEN(B8) -> 105 | D8: n010701d | E8: {=_xlfn.IFS(IFERROR(FIND("M-3SII",B8),-1)>0,"J_M3S2",IFERROR(FIND("M-V",B8),-1)>0,"J_M5",IFERROR(FIND("M-4S",B8),-1)>0,"J_M4S",IFERROR(FIND("M-3C",B8),-1)>0,"J_M3C",IFERROR(FIND("M-3S",B8),-1)>0,"J_M3S",IFERROR(FIND("M-3H",B8),-1)>0,"J_M3H",IFERROR(FIND("H-IIA",B8),-1)>0,"J_H2A",IFERROR(FIND("H-IIB",B8),-1)>0,"J_H2B",IFERROR(FIND("H-II",B8),-1)>0,"J_H2",IFERROR(FIND("H-I",B8),-1)>0,"J_H1",IFERROR(FIND("N-II",B8),-1)>0,"J_N2",IFERROR(FIND("N-I",B8),-1)>0,"J_N1",IFERROR(FIND("イプシロン",B8),-1)>0,"J_E",TRUE,"")} | G8: =IF(E8<>"",E8&"_"&F8,"")
A9: 01/08 07:00:00 | B9: 【今日の人工衛星】1/8 1985年：さきがけ 日本のハレー彗星探査機。8/19に打ち上げられた「すいせい」の姉妹機にあたり、さきがけでの経験が「すいせい」にフィードバックされた。 | C9: =LEN(B9) -> 90 | D9: n010801d | E9: J_M3S2 | F9: 1 | G9: =IF(E9<>"",E9&"_"&F9,"") -> J_M3S2_1
A10: 01/08 04:26:00 | B10: ★1985年の今日1/8 4:26、M-3SIIロケット1号機でハレー彗星探査試験機さきがけが打ち上げられました。 | C10: =LEN(B10) -> 57 | D10: n010801t1 | E10: {=_xlfn.IFS(IFERROR(FIND("M-3SII",B10),-1)>0,"J_M3S2",IFERROR(FIND("M-V",B10),-1)>0,"J_M5",IFERROR(FIND("M-4S",B10),-1)>0,"J_M4S",IFERROR(FIND("M-3C",B10),-1)>0,"J_M3C",IFERROR(FIND("M-3S",B10),-1)>0,"J_M3S",IFERROR(FIND("M-3H",B10),-1)>0,"J_M3H",IFERROR(FIND("H-IIA",B10),-1)>0,"J_H2A",IFERROR(FIND("H-IIB",B10),-1)>0,"J_H2B",IFERROR(FIND("H-II",B10),-1)>0,"J_H2",IFERROR(FIND("H-I",B10),-1)>0,"J_H1",IFERROR(FIND("N-II",B10),-1)>0,"J_N2",IFERROR(FIND("N-I",B10),-1)>0,"J_N1",IFERROR(FIND("イプシロン",B10),-1)>0,"J_E",TRUE,"")} -> J_M3S2 | F10: 1 | G10: =IF(E10<>"",E10&"_"&F10,"") -> J_M3S2_1
A11: 01/09 07:00:00 | B11: 【今日の人工衛星】1/9 1990年：STS-32 スペースシャトル・コロンビアの打上。通信衛星の打ち上げと、長期暴露試験衛星LDEFの回収が目的。LDEFは6年間も宇宙を漂っていた。 | C11: =LEN(B11) -> 92 | D11: n010901d | E11: {=_xlfn.IFS(IFERROR(FIND("M-3SII",B11),-1)>0,"J_M3S2",IFERROR(FIND("M-V",B11),-1)>0,"J_M5",IFERROR(FIND("M-4S",B11),-1)>0,"J_M4S",IFERROR(FIND("M-3C",B11),-1)>0,"J_M3C",IFERROR(FIND("M-3S",B11),-1)>0,"J_M3S",IFERROR(FIND("M-3H",B11),-1)>0,"J_M3H",IFERROR(FIND("H-IIA",B11),-1)>0,"J_H2A",IFERROR(FIND("H-IIB",B11),-1)>0,"J_H2B",IFERROR(FIND("H-II",B11),-1)>0,"J_H2",IFERROR(FIND("H-I",B11),-1)>0,"J_H1",IFERROR(FIND("N-II",B11),-1)>0,"J_N2",IFERROR(FIND("N-I",B11),-1)>0,"J_N1",IFERROR(FIND("イプシロン",B11),-1)>0,"J_E",TRUE,"")} | G11: =IF(E11<>"",E11&"_"&F11,"")
A12: 01/10 07:00:00 | B12: 【今日の人工衛星】1/10 1969年：ベネラ6号 旧ソ連の金星探査機。ベネラ4号の観測結果を踏まえた改良がなされた、1/5打上の5号の同型機。5,6号ともに金星に無事到達、降下カプセル投下にも成功。 | C12: =LEN(B12) -> 100 | D12: n011001d | E12: {=_xlfn.IFS(IFERROR(FIND("M-3SII",B12),-1)>0,"J_M3S2",IFERROR(FIND("M-V",B12),-1)>0,"J_M5",IFERROR(FIND("M-4S",B12),-1)>0,"J_M4S",IFERROR(FIND("M-3C",B12),-1)>0,"J_M3C",IFERROR(FIND("M-3S",B12),-1)>0,"J_M3S",IFERROR(FIND("M-3H",B12),-1)>0,"J_M3H",IFERROR(FIND("H-IIA",B12),-1)>0,"J_H2A",IFERROR(FIND("H-IIB",B12),-1)>0,"J_H2B",IFERROR(FIND("H-II",B12),-1)>0,"J_H2",IFERROR(FIND("H-I",B12),-1)>0,"J_H1",IFERROR(FIND("N-II",B12),-1)>0,"J_N2",IFERROR(FIND("N-I",B12),-1)>0,"J_N1",IFERROR(FIND("イプシロン",B12),-1)>0,"J_E",TRUE,"")} | G12: =IF(E12<>"",E12&"_"&F12,"")
A13: 01/11 07:00:00 | B13: 【今日の人工衛星】1/11 1996年：STS-72 エンデバーの打上、若田光一飛行士の初のフライト。H-IIロケットで打ち上げた宇宙実験・観測フリーフライヤ (SFU)の回収が主な目的であった | C13: =LEN(B13) -> 97 | D13: n011101d | G13: =IF(E13<>"",E13&"_"&F13,"")
A14: 01/12 07:00:00 | B14: 【今日の人工衛星】1/12 2005年：ディープインパクト アメリカの探査機。テンペル１彗星に衝突体を衝突させ、クレーターを生成、彗星の内部構造を調査するもの。調査は無事成功。現在はエキポシと改名、他の彗星などを観測 | C14: =LEN(B14) -> 108 | D14: n011201d | E14: {=_xlfn.IFS(IFERROR(FIND("M-3SII",B14),-1)>0,"J_M3S2",IFERROR(FIND("M-V",B14),-1)>0,"J_M5",IFERROR(FIND("M-4S",B14),-1)>0,"J_M4S",IFERROR(FIND("M-3C",B14),-1)>0,"J_M3C",IFERROR(FIND("M-3S",B14),-1)>0,"J_M3S",IFERROR(FIND("M-3H",B14),-1)>0,"J_M3H",IFERROR(FIND("H-IIA",B14),-1)>0,"J_H2A",IFERROR(FIND("H-IIB",B14),-1)>0,"J_H2B",IFERROR(FIND("H-II",B14),-1)>0,"J_H2",IFERROR(FIND("H-I",B14),-1)>0,"J_H1",IFERROR(FIND("N-II",B14),-1)>0,"J_N2",IFERROR(FIND("N-I",B14),-1)>0,"J_N1",IFERROR(FIND("イプシロン",B14),-1)>0,"J_E",TRUE,"")} | G14: =IF(E14<>"",E14&"_"&F14,"")
A15: 01/13 07:00:00 | B15: 【今日の人工衛星】1/13 1993年：STS-54 スペースシャトル・エンデバーの5回目の打上。データ中継衛星TDRS-Fの打上などを実施。 | C15: =LEN(B15) -> 71 | D15: n011301d | E15: {=_xlfn.IFS(IFERROR(FIND("M-3SII",B15),-1)>0,"J_M3S2",IFERROR(FIND("M-V",B15),-1)>0,"J_M5",IFERROR(FIND("M-4S",B15),-1)>0,"J_M4S",IFERROR(FIND("M-3C",B15),-1)>0,"J_M3C",IFERROR(FIND("M-3S",B15),-1)>0,"J_M3S",IFERROR(FIND("M-3H",B15),-1)>0,"J_M3H",IFERROR(FIND("H-IIA",B15),-1)>0,"J_H2A",IFERROR(FIND("H-IIB",B15),-1)>0,"J_H2B",IFERROR(FIND("H-II",B15),-1)>0,"J_H2",IFERROR(FIND("H-I",B15),-1)>0,"J_H1",IFERROR(FIND("N-II",B15),-1)>0,"J_N2",IFERROR(FIND("N-I",B15),-1)>0,"J_N1",IFERROR(FIND("イプシロン",B15),-1)>0,"J_E",TRUE,"")} | G15: =IF(E15<>"",E15&"_"&F15,"")
A16: 01/14 07:00:00 | B16: 【今日の人工衛星】1/14 1996年：Koreasat2 韓国通信(KT)が保有する通信・放送衛星。放送衛星の任務はKoreasat3に引き継がれている。 | C16: =LEN(B16) -> 78 | D16: n011401d | E16: {=_xlfn.IFS(IFERROR(FIND("M-3SII",B16),-1)>0,"J_M3S2",IFERROR(FIND("M-V",B16),-1)>0,"J_M5",IFERROR(FIND("M-4S",B16),-1)>0,"J_M4S",IFERROR(FIND("M-3C",B16),-1)>0,"J_M3C",IFERROR(FIND("M-3S",B16),-1)>0,"J_M3S",IFERROR(FIND("M-3H",B16),-1)>0,"J_M3H",IFERROR(FIND("H-IIA",B16),-1)>0,"J_H2A",IFERROR(FIND("H-IIB",B16),-1)>0,"J_H2B",IFERROR(FIND("H-II",B16),-1)>0,"J_H2",IFERROR(FIND("H-I",B16),-1)>0,"J_H1",IFERROR(FIND("N-II",B16),-1)>0,"J_N2",IFERROR(FIND("N-I",B16),-1)>0,"J_N1",IFERROR(FIND("イプシロン",B16),-1)>0,"J_E",TRUE,"")} | G16: =IF(E16<>"",E16&"_"&F16,"")
A17: 01/15 07:00:00 | B17: 【今日の人工衛星】1/15 1991年：Italsat 1 イタリア初の実用の通信衛星。12,000回線分の通信が可能。現在は引退し墓場軌道に移っている | C17: =LEN(B17) -> 76 | D17: n011501d | E17: {=_xlfn.IFS(IFERROR(FIND("M-3SII",B17),-1)>0,"J_M3S2",IFERROR(FIND("M-V",B17),-1)>0,"J_M5",IFERROR(FIND("M-4S",B17),-1)>0,"J_M4S",IFERROR(FIND("M-3C",B17),-1)>0,"J_M3C",IFERROR(FIND("M-3S",B17),-1)>0,"J_M3S",IFERROR(FIND("M-3H",B17),-1)>0,"J_M3H",IFERROR(FIND("H-IIA",B17),-1)>0,"J_H2A",IFERROR(FIND("H-IIB",B17),-1)>0,"J_H2B",IFERROR(FIND("H-II",B17),-1)>0,"J_H2",IFERROR(FIND("H-I",B17),-1)>0,"J_H1",IFERROR(FIND("N-II",B17),-1)>0,"J_N2",IFERROR(FIND("N-I",B17),-1)>0,"J_N1",IFERROR(FIND("イプシロン",B17),-1)>0,"J_E",TRUE,"")} | G17: =IF(E17<>"",E17&"_"&F17,"")
A18: 01/15 07:01:00 | B18: 【今日の人工衛星】1/15 1995年：自立帰還型無人宇宙実験システム(EXPRESS) M-3SIIロケット8号機で打上。軌道再突入試験を目的としていたが実験は失敗。機体はガーナに着陸しており、翌年回収された。 | C18: =LEN(B18) -> 106 | D18: n011502d | E18: {=_xlfn.IFS(IFERROR(FIND("M-3SII",B18),-1)>0,"J_M3S2",IFERROR(FIND("M-V",B18),-1)>0,"J_M5",IFERROR(FIND("M-4S",B18),-1)>0,"J_M4S",IFERROR(FIND("M-3C",B18),-1)>0,"J_M3C",IFERROR(FIND("M-3S",B18),-1)>0,"J_M3S",IFERROR(FIND("M-3H",B18),-1)>0,"J_M3H",IFERROR(FIND("H-IIA",B18),-1)>0,"J_H2A",IFERROR(FIND("H-IIB",B18),-1)>0,"J_H2B",IFERROR(FIND("H-II",B18),-1)>0,"J_H2",IFERROR(FIND("H-I",B18),-1)>0,"J_H1",IFERROR(FIND("N-II",B18),-1)>0,"J_N2",IFERROR(FIND("N-I",B18),-1)>0,"J_N1",IFERROR(FIND("イプシロン",B18),-1)>0,"J_E",TRUE,"")} -> J_M3S2 | F18: 8 | G18: =IF(E18<>"",E18&"_"&F18,"") -> J_M3S2_8
A19: 01/15 22:45:00 | B19: ★1995年の今日1/15 22:45、M-3SIIロケット8号機で自立帰還型無人宇宙実験システム(EXPRESS) が打ち上げられました。重量過多による異常振動のため予定の軌道には投入できず実験は失敗しました。機体自体は翌年回収されました。 | C19: =LEN(B19) -> 121 | D19: n011502t1 | E19: {=_xlfn.IFS(IFERROR(FIND("M-3SII",B19),-1)>0,"J_M3S2",IFERROR(FIND("M-V",B19),-1)>0,"J_M5",IFERROR(FIND("M-4S",B19),-1)>0,"J_M4S",IFERROR(FIND("M-3C",B19),-1)>0,"J_M3C",IFERROR(FIND("M-3S",B19),-1)>0,"J_M3S",IFERROR(FIND("M-3H",B19),-1)>0,"J_M3H",IFERROR(FIND("H-IIA",B19),-1)>0,"J_H2A",IFERROR(FIND("H-IIB",B19),-1)>0,"J_H2B",IFERROR(FIND("H-II",B19),-1)>0,"J_H2",IFERROR(FIND("H-I",B19),-1)>0,"J_H1",IFERROR(FIND("N-II",B19),-1)>0,"J_N2",IFERROR(FIND("N-I",B19),-1)>0,"J_N1",IFERROR(FIND("イプシロン",B19),-1)>0,"J_E",TRUE,"")} -> J_M3S2 | F19: 8 | G19: =IF(E19<>"",E19&"_"&F19,"") -> J_M3S2_8
A20: 01/16 07:00:00 | B20: 【今日の人工衛星】1/16 2003年：STS-107 スペースシャトル・コロンビアの打上。コロンビアは、同年2月1日の地球帰還時に空中分解事故を起こしている。 | C20: =LEN(B20) -> 81 | D20: n011601d | E20: {=_xlfn.IFS(IFERROR(FIND("M-3SII",B20),-1)>0,"J_M3S2",IFERROR(FIND("M-V",B20),-1)>0,"J_M5",IFERROR(FIND("M-4S",B20),-1)>0,"J_M4S",IFERROR(FIND("M-3C",B20),-1)>0,"J_M3C",IFERROR(FIND("M-3S",B20),-1)>0,"J_M3S",IFERROR(FIND("M-3H",B20),-1)>0,"J_M3H",IFERROR(FIND("H-IIA",B20),-1)>0,"J_H2A",IFERROR(FIND("H-IIB",B20),-1)>0,"J_H2B",IFERROR(FIND("H-II",B20),-1)>0,"J_H2",IFERROR(FIND("H-I",B20),-1)>0,"J_H1",IFERROR(FIND("N-II",B20),-1)>0,"J_N2",IFERROR(FIND("N-I",B20),-1)>0,"J_N1",IFERROR(FIND("イプシロン",B20),-1)>0,"J_E",TRUE,"")} | G20: =IF(E20<>"",E20&"_"&F20,"")
A21: 01/17 07:00:00 | B21: 【今日の人工衛星】1/17 1968年：Ferret 11 アメリカの軍事衛星。ソ連の防空レーダーの観測、音声通信の傍受、ミサイルや衛星の通信の記録などを行った | C21: =LEN(B21) -> 80 | D21: n011701d | E21: {=_xlfn.IFS(IFERROR(FIND("M-3SII",B21),-1)>0,"J_M3S2",IFERROR(FIND("M-V",B21),-1)>0,"J_M5",IFERROR(FIND("M-4S",B21),-1)>0,"J_M4S",IFERROR(FIND("M-3C",B21),-1)>0,"J_M3C",IFERROR(FIND("M-3S",B21),-1)>0,"J_M3S",IFERROR(FIND("M-3H",B21),-1)>0,"J_M3H",IFERROR(FIND("H-IIA",B21),-1)>0,"J_H2A",IFERROR(FIND("H-IIB",B21),-1)>0,"J_H2B",IFERROR(FIND("H-II",B21),-1)>0,"J_H2",IFERROR(FIND("H-I",B21),-1)>0,"J_H1",IFERROR(FIND("N-II",B21),-1)>0,"J_N2",IFERROR(FIND("N-I",B21),-1)>0,"J_N1",IFERROR(FIND("イプシロン",B21),-1)>0,"J_E",TRUE,"")} | G21: =IF(E21<>"",E21&"_"&F21,"")
A22: 01/18 07:00:00 | B22: 【今日の人工衛星】1/18 1963年：1965-003A アメリカ空軍の打ち上げた物体。詳細情報はNSSDCからは確認できず。1979年に消滅した模様。 | C22: =LEN(B22) -> 77 | D22: n011801d | E22: {=_xlfn.IFS(IFERROR(FIND("M-3SII",B22),-1)>0,"J_M3S2",IFERROR(FIND("M-V",B22),-1)>0,"J_M5",IFERROR(FIND("M-4S",B22),-1)>0,"J_M4S",IFERROR(FIND("M-3C",B22),-1)>0,"J_M3C",IFERROR(FIND("M-3S",B22),-1)>0,"J_M3S",IFERROR(FIND("M-3H",B22),-1)>0,"J_M3H",IFERROR(FIND("H-IIA",B22),-1)>0,"J_H2A",IFERROR(FIND("H-IIB",B22),-1)>0,"J_H2B",IFERROR(FIND("H-II",B22),-1)>0,"J_H2",IFERROR(FIND("H-I",B22),-1)>0,"J_H1",IFERROR(FIND("N-II",B22),-1)>0,"J_N2",IFERROR(FIND("N-I",B22),-1)>0,"J_N1",IFERROR(FIND("イプシロン",B22),-1)>0,"J_E",TRUE,"")} | G22: =IF(E22<>"",E22&"_"&F22,"")
A23: 01/19 07:00:00 | B23: 【今日の人工衛星】1/19 2006年：ニューホライズンズ アメリカの惑星探査機。人類初の冥王星探査機である。打ち上げ直後の速度30km/sは史上最速、月軌道および木星までも史上最速で駆け抜け、冥王星を2015年から2016年にかけて探査。その後は太陽系外縁天体を観測予定。 | C23: =LEN(B23) -> 137 | D23: n011901d | E23: {=_xlfn.IFS(IFERROR(FIND("M-3SII",B23),-1)>0,"J_M3S2",IFERROR(FIND("M-V",B23),-1)>0,"J_M5",IFERROR(FIND("M-4S",B23),-1)>0,"J_M4S",IFERROR(FIND("M-3C",B23),-1)>0,"J_M3C",IFERROR(FIND("M-3S",B23),-1)>0,"J_M3S",IFERROR(FIND("M-3H",B23),-1)>0,"J_M3H",IFERROR(FIND("H-IIA",B23),-1)>0,"J_H2A",IFERROR(FIND("H-IIB",B23),-1)>0,"J_H2B",IFERROR(FIND("H-II",B23),-1)>0,"J_H2",IFERROR(FIND("H-I",B23),-1)>0,"J_H1",IFERROR(FIND("N-II",B23),-1)>0,"J_N2",IFERROR(FIND("N-I",B23),-1)>0,"J_N1",IFERROR(FIND("イプシロン",B23),-1)>0,"J_E",TRUE,"")} | G23: =IF(E23<>"",E23&"_"&F23,"") | H23: 20180404 | I23: 修正
A24: 01/20 07:00:00 | B24: 【今日の人工衛星】1/20 1978年：プログレス1号 旧ソ連・ロシアの宇宙補給船プログレスの初号機。サリュート6号への物資輸送に使用した。その後プログレスは42機作成、現在は次々世代のプログレスが使用されている | C24: =LEN(B24) -> 106 | D24: n012001d | E24: {=_xlfn.IFS(IFERROR(FIND("M-3SII",B24),-1)>0,"J_M3S2",IFERROR(FIND("M-V",B24),-1)>0,"J_M5",IFERROR(FIND("M-4S",B24),-1)>0,"J_M4S",IFERROR(FIND("M-3C",B24),-1)>0,"J_M3C",IFERROR(FIND("M-3S",B24),-1)>0,"J_M3S",IFERROR(FIND("M-3H",B24),-1)>0,"J_M3H",IFERROR(FIND("H-IIA",B24),-1)>0,"J_H2A",IFERROR(FIND("H-IIB",B24),-1)>0,"J_H2B",IFERROR(FIND("H-II",B24),-1)>0,"J_H2",IFERROR(FIND("H-I",B24),-1)>0,"J_H1",IFERROR(FIND("N-II",B24),-1)>0,"J_N2",IFERROR(FIND("N-I",B24),-1)>0,"J_N1",IFERROR(FIND("イプシロン",B24),-1)>0,"J_E",TRUE,"")} | G24: =IF(E24<>"",E24&"_"&F24,"")
A25: 01/21 07:00:00 | B25: 【今日の人工衛星】1/21 1964年：Relay 2 アメリカの実験通信衛星。初の太平洋横断TV中継を行ったのはRelay1だが、その同型機 | C25: =LEN(B25) -> 71 | D25: n012101d | E25: {=_xlfn.IFS(IFERROR(FIND("M-3SII",B25),-1)>0,"J_M3S2",IFERROR(FIND("M-V",B25),-1)>0,"J_M5",IFERROR(FIND("M-4S",B25),-1)>0,"J_M4S",IFERROR(FIND("M-3C",B25),-1)>0,"J_M3C",IFERROR(FIND("M-3S",B25),-1)>0,"J_M3S",IFERROR(FIND("M-3H",B25),-1)>0,"J_M3H",IFERROR(FIND("H-IIA",B25),-1)>0,"J_H2A",IFERROR(FIND("H-IIB",B25),-1)>0,"J_H2B",IFERROR(FIND("H-II",B25),-1)>0,"J_H2",IFERROR(FIND("H-I",B25),-1)>0,"J_H1",IFERROR(FIND("N-II",B25),-1)>0,"J_N2",IFERROR(FIND("N-I",B25),-1)>0,"J_N1",IFERROR(FIND("イプシロン",B25),-1)>0,"J_E",TRUE,"")} | G25: =IF(E25<>"",E25&"_"&F25,"")
A26: 01/22 07:00:00 | B26: 【今日の人工衛星】1/22 2011年：HTV-2 日本の宇宙ステーション補給機の2号。このときから「こうのとり」の愛称がつけられた。国際宇宙ステーションへの補給を無事に完了した。 | C26: =LEN(B26) -> 90 | D26: n012201d | E26: J_H2B | F26: 2 | G26: =IF(E26<>"",E26&"_"&F26,"") -> J_H2B_2
A27: 01/22 14:37:57 | B27: ★2011年の今日1/22 14:37、H-IIBロケット2号機で宇宙ステーション補給機こうのとり2号機(HTV-2)が打ち上げられました。 | C27: =LEN(B27) -> 70 | D27: n012201t1 | E27: {=_xlfn.IFS(IFERROR(FIND("M-3SII",B27),-1)>0,"J_M3S2",IFERROR(FIND("M-V",B27),-1)>0,"J_M5",IFERROR(FIND("M-4S",B27),-1)>0,"J_M4S",IFERROR(FIND("M-3C",B27),-1)>0,"J_M3C",IFERROR(FIND("M-3S",B27),-1)>0,"J_M3S",IFERROR(FIND("M-3H",B27),-1)>0,"J_M3H",IFERROR(FIND("H-IIA",B27),-1)>0,"J_H2A",IFERROR(FIND("H-IIB",B27),-1)>0,"J_H2B",IFERROR(FIND("H-II",B27),-1)>0,"J_H2",IFERROR(FIND("H-I",B27),-1)>0,"J_H1",IFERROR(FIND("N-II",B27),-1)>0,"J_N2",IFERROR(FIND("N-I",B27),-1)>0,"J_N1",IFERROR(FIND("イプシロン",B27),-1)>0,"J_E",TRUE,"")} -> J_H2B | F27: 2 | G27: =IF(E27<>"",E27&"_"&F27,"") -> J_H2B_2
A28: 01/23 07:00:00 | B28: 【今日の人工衛星】1/23 1984年：ゆり2号a 日本の放送衛星。打ち上げ直後に太陽電池の故障が見つかったため、NHKの衛星放送は2チャンネルの予定を1チャンネルに縮小することを余儀なくされた | C28: =LEN(B28) -> 97 | D28: n012301d | E28: {=_xlfn.IFS(IFERROR(FIND("M-3SII",B28),-1)>0,"J_M3S2",IFERROR(FIND("M-V",B28),-1)>0,"J_M5",IFERROR(FIND("M-4S",B28),-1)>0,"J_M4S",IFERROR(FIND("M-3C",B28),-1)>0,"J_M3C",IFERROR(FIND("M-3S",B28),-1)>0,"J_M3S",IFERROR(FIND("M-3H",B28),-1)>0,"J_M3H",IFERROR(FIND("H-IIA",B28),-1)>0,"J_H2A",IFERROR(FIND("H-IIB",B28),-1)>0,"J_H2B",IFERROR(FIND("H-II",B28),-1)>0,"J_H2",IFERROR(FIND("H-I",B28),-1)>0,"J_H1",IFERROR(FIND("N-II",B28),-1)>0,"J_N2",IFERROR(FIND("N-I",B28),-1)>0,"J_N1",IFERROR(FIND("イプシロン",B28),-1)>0,"J_E",TRUE,"")} | G28: =IF(E28<>"",E28&"_"&F28,"")
A29: 01/23 07:01:00 | B29: 【今日の人工衛星】1/23 2009年：いぶき 日本の地球観測衛星。温室効果ガス測定を目的としている。当初の計画に変更が加えられ、京都議定書への寄与する観測に重点が絞られている | C29: =LEN(B29) -> 88 | D29: n012302d | E29: J_H2A | F29: 15 | G29: =IF(E29<>"",E29&"_"&F29,"") -> J_H2A_15
A30: 01/23 12:54:00 | B30: ★2009年の今日1/23 12:54、H-IIAロケット15号機で温室効果ガス観測技術衛星いぶき（GOSAT）と相乗り衛星7基が打ち上げられました。 | C30: =LEN(B30) -> 75 | D30: n012302t1 | E30: {=_xlfn.IFS(IFERROR(FIND("M-3SII",B30),-1)>0,"J_M3S2",IFERROR(FIND("M-V",B30),-1)>0,"J_M5",IFERROR(FIND("M-4S",B30),-1)>0,"J_M4S",IFERROR(FIND("M-3C",B30),-1)>0,"J_M3C",IFERROR(FIND("M-3S",B30),-1)>0,"J_M3S",IFERROR(FIND("M-3H",B30),-1)>0,"J_M3H",IFERROR(FIND("H-IIA",B30),-1)>0,"J_H2A",IFERROR(FIND("H-IIB",B30),-1)>0,"J_H2B",IFERROR(FIND("H-II",B30),-1)>0,"J_H2",IFERROR(FIND("H-I",B30),-1)>0,"J_H1",IFERROR(FIND("N-II",B30),-1)>0,"J_N2",IFERROR(FIND("N-I",B30),-1)>0,"J_N1",IFERROR(FIND("イプシロン",B30),-1)>0,"J_E",TRUE,"")} -> J_H2A | F30: 15 | G30: =IF(E30<>"",E30&"_"&F30,"") -> J_H2A_15
A31: 01/23 13:18:00 | B31: ★H-IIAロケット15号機の打上から24分後、小型実証衛星1型（JAXA）が分離されました。 | C31: =LEN(B31) -> 47 | D31: n012302t2 | E31: {=_xlfn.IFS(IFERROR(FIND("M-3SII",B31),-1)>0,"J_M3S2",IFERROR(FIND("M-V",B31),-1)>0,"J_M5",IFERROR(FIND("M-4S",B31),-1)>0,"J_M4S",IFERROR(FIND("M-3C",B31),-1)>0,"J_M3C",IFERROR(FIND("M-3S",B31),-1)>0,"J_M3S",IFERROR(FIND("M-3H",B31),-1)>0,"J_M3H",IFERROR(FIND("H-IIA",B31),-1)>0,"J_H2A",IFERROR(FIND("H-IIB",B31),-1)>0,"J_H2B",IFERROR(FIND("H-II",B31),-1)>0,"J_H2",IFERROR(FIND("H-I",B31),-1)>0,"J_H1",IFERROR(FIND("N-II",B31),-1)>0,"J_N2",IFERROR(FIND("N-I",B31),-1)>0,"J_N1",IFERROR(FIND("イプシロン",B31),-1)>0,"J_E",TRUE,"")} -> J_H2A | F31: 15 | G31: =IF(E31<>"",E31&"_"&F31,"") -> J_H2A_15
A32: 01/23 13:22:00 | B32: ★H-IIAロケット15号機の打上から28分後、雷神（東北大・スプライト観測衛星）が分離されました。 | C32: =LEN(B32) -> 50 | D32: n012302t3 | E32: {=_xlfn.IFS(IFERROR(FIND("M-3SII",B32),-1)>0,"J_M3S2",IFERROR(FIND("M-V",B32),-1)>0,"J_M5",IFERROR(FIND("M-4S",B32),-1)>0,"J_M4S",IFERROR(FIND("M-3C",B32),-1)>0,"J_M3C",IFERROR(FIND("M-3S",B32),-1)>0,"J_M3S",IFERROR(FIND("M-3H",B32),-1)>0,"J_M3H",IFERROR(FIND("H-IIA",B32),-1)>0,"J_H2A",IFERROR(FIND("H-IIB",B32),-1)>0,"J_H2B",IFERROR(FIND("H-II",B32),-1)>0,"J_H2",IFERROR(FIND("H-I",B32),-1)>0,"J_H1",IFERROR(FIND("N-II",B32),-1)>0,"J_N2",IFERROR(FIND("N-I",B32),-1)>0,"J_N1",IFERROR(FIND("イプシロン",B32),-1)>0,"J_E",TRUE,"")} -> J_H2A | F32: 15 | G32: =IF(E32<>"",E32&"_"&F32,"") -> J_H2A_15
A33: 01/23 13:26:00 | B33: ★H-IIAロケット15号機の打上から32分後、まいど1号（東大阪宇宙開発協同組合）が分離されました。 | C33: =LEN(B33) -> 51 | D33: n012302t4 | E33: {=_xlfn.IFS(IFERROR(FIND("M-3SII",B33),-1)>0,"J_M3S2",IFERROR(FIND("M-V",B33),-1)>0,"J_M5",IFERROR(FIND("M-4S",B33),-1)>0,"J_M4S",IFERROR(FIND("M-3C",B33),-1)>0,"J_M3C",IFERROR(FIND("M-3S",B33),-1)>0,"J_M3S",IFERROR(FIND("M-3H",B33),-1)>0,"J_M3H",IFERROR(FIND("H-IIA",B33),-1)>0,"J_H2A",IFERROR(FIND("H-IIB",B33),-1)>0,"J_H2B",IFERROR(FIND("H-II",B33),-1)>0,"J_H2",IFERROR(FIND("H-I",B33),-1)>0,"J_H1",IFERROR(FIND("N-II",B33),-1)>0,"J_N2",IFERROR(FIND("N-I",B33),-1)>0,"J_N1",IFERROR(FIND("イプシロン",B33),-1)>0,"J_E",TRUE,"")} -> J_H2A | F33: 15 | G33: =IF(E33<>"",E33&"_"&F33,"") -> J_H2A_15
A34: 01/23 13:30:00 | B34: ★H-IIAロケット15号機の打上から36分後、かがやき（ソラン（株））が分離されました。 | C34: =LEN(B34) -> 45 | D34: n012302t5 | E34: {=_xlfn.IFS(IFERROR(FIND("M-3SII",B34),-1)>0,"J_M3S2",IFERROR(FIND("M-V",B34),-1)>0,"J_M5",IFERROR(FIND("M-4S",B34),-1)>0,"J_M4S",IFERROR(FIND("M-3C",B34),-1)>0,"J_M3C",IFERROR(FIND("M-3S",B34),-1)>0,"J_M3S",IFERROR(FIND("M-3H",B34),-1)>0,"J_M3H",IFERROR(FIND("H-IIA",B34),-1)>0,"J_H2A",IFERROR(FIND("H-IIB",B34),-1)>0,"J_H2B",IFERROR(FIND("H-II",B34),-1)>0,"J_H2",IFERROR(FIND("H-I",B34),-1)>0,"J_H1",IFERROR(FIND("N-II",B34),-1)>0,"J_N2",IFERROR(FIND("N-I",B34),-1)>0,"J_N1",IFERROR(FIND("イプシロン",B34),-1)>0,"J_E",TRUE,"")} -> J_H2A | F34: 15 | G34: =IF(E34<>"",E34&"_"&F34,"") -> J_H2A_15
A35: 01/23 13:34:00 | B35: ★H-IIAロケット15号機の打上から40分後、輝汐（航空高専）が分離されました。 | C35: =LEN(B35) -> 41 | D35: n012302t6 | E35: {=_xlfn.IFS(IFERROR(FIND("M-3SII",B35),-1)>0,"J_M3S2",IFERROR(FIND("M-V",B35),-1)>0,"J_M5",IFERROR(FIND("M-4S",B35),-1)>0,"J_M4S",IFERROR(FIND("M-3C",B35),-1)>0,"J_M3C",IFERROR(FIND("M-3S",B35),-1)>0,"J_M3S",IFERROR(FIND("M-3H",B35),-1)>0,"J_M3H",IFERROR(FIND("H-IIA",B35),-1)>0,"J_H2A",IFERROR(FIND("H-IIB",B35),-1)>0,"J_H2B",IFERROR(FIND("H-II",B35),-1)>0,"J_H2",IFERROR(FIND("H-I",B35),-1)>0,"J_H1",IFERROR(FIND("N-II",B35),-1)>0,"J_N2",IFERROR(FIND("N-I",B35),-1)>0,"J_N1",IFERROR(FIND("イプシロン",B35),-1)>0,"J_E",TRUE,"")} -> J_H2A | F35: 15 | G35: =IF(E35<>"",E35&"_"&F35,"") -> J_H2A_15
A36: 01/23 13:39:00 | B36: ★H-IIAロケット15号機の打上から45分後、空海（香川大学）が分離されました。 | C36: =LEN(B36) -> 41 | D36: n012302t7 | E36: {=_xlfn.IFS(IFERROR(FIND("M-3SII",B36),-1)>0,"J_M3S2",IFERROR(FIND("M-V",B36),-1)>0,"J_M5",IFERROR(FIND("M-4S",B36),-1)>0,"J_M4S",IFERROR(FIND("M-3C",B36),-1)>0,"J_M3C",IFERROR(FIND("M-3S",B36),-1)>0,"J_M3S",IFERROR(FIND("M-3H",B36),-1)>0,"J_M3H",IFERROR(FIND("H-IIA",B36),-1)>0,"J_H2A",IFERROR(FIND("H-IIB",B36),-1)>0,"J_H2B",IFERROR(FIND("H-II",B36),-1)>0,"J_H2",IFERROR(FIND("H-I",B36),-1)>0,"J_H1",IFERROR(FIND("N-II",B36),-1)>0,"J_N2",IFERROR(FIND("N-I",B36),-1)>0,"J_N1",IFERROR(FIND("イプシロン",B36),-1)>0,"J_E",TRUE,"")} -> J_H2A | F36: 15 | G36: =IF(E36<>"",E36&"_"&F36,"") -> J_H2A_15
A37: 01/23 13:43:00 | B37: ★H-IIAロケット15号機の打上から49分後、ひとみ（PRISM、東京大学）が分離されました。ひとみ（PRISM）は2025年4月19日に大気圏に再突入しました。 https://www.n2yo.com/satellite/?s=33493 | C37: =LEN(B37) -> 122 | D37: n012302t8 | E37: {=_xlfn.IFS(IFERROR(FIND("M-3SII",B37),-1)>0,"J_M3S2",IFERROR(FIND("M-V",B37),-1)>0,"J_M5",IFERROR(FIND("M-4S",B37),-1)>0,"J_M4S",IFERROR(FIND("M-3C",B37),-1)>0,"J_M3C",IFERROR(FIND("M-3S",B37),-1)>0,"J_M3S",IFERROR(FIND("M-3H",B37),-1)>0,"J_M3H",IFERROR(FIND("H-IIA",B37),-1)>0,"J_H2A",IFERROR(FIND("H-IIB",B37),-1)>0,"J_H2B",IFERROR(FIND("H-II",B37),-1)>0,"J_H2",IFERROR(FIND("H-I",B37),-1)>0,"J_H1",IFERROR(FIND("N-II",B37),-1)>0,"J_N2",IFERROR(FIND("N-I",B37),-1)>0,"J_N1",IFERROR(FIND("イプシロン",B37),-1)>0,"J_E",TRUE,"")} -> J_H2A | F37: 15 | G37: =IF(E37<>"",E37&"_"&F37,"") -> J_H2A_15 | H37: 20250620 | I37: 追記
A38: 01/24 07:00:00 | B38: 【今日の人工衛星】1/24 2006年：ALOS[だいち] 地球観測衛星、H-IIA 8号機で10:33に打ち上げ。東日本大震災直後の被災地の観測も行っていたが、2011年4月22日に活動が停止してしまい、5月12日に運用が停止された。 | C38: =LEN(B38) -> 118 | D38: n012401d | E38: J_H2A | F38: 8 | G38: =IF(E38<>"",E38&"_"&F38,"") -> J_H2A_8
A39: 01/24 10:33:00 | B39: ★2006年の今日1/24 10:33、H-IIAロケット8号機で地球観測衛星だいち(ALOS)が打ち上げられました。 | C39: =LEN(B39) -> 59 | D39: n012401t1 | E39: {=_xlfn.IFS(IFERROR(FIND("M-3SII",B39),-1)>0,"J_M3S2",IFERROR(FIND("M-V",B39),-1)>0,"J_M5",IFERROR(FIND("M-4S",B39),-1)>0,"J_M4S",IFERROR(FIND("M-3C",B39),-1)>0,"J_M3C",IFERROR(FIND("M-3S",B39),-1)>0,"J_M3S",IFERROR(FIND("M-3H",B39),-1)>0,"J_M3H",IFERROR(FIND("H-IIA",B39),-1)>0,"J_H2A",IFERROR(FIND("H-IIB",B39),-1)>0,"J_H2B",IFERROR(FIND("H-II",B39),-1)>0,"J_H2",IFERROR(FIND("H-I",B39),-1)>0,"J_H1",IFERROR(FIND("N-II",B39),-1)>0,"J_N2",IFERROR(FIND("N-I",B39),-1)>0,"J_N1",IFERROR(FIND("イプシロン",B39),-1)>0,"J_E",TRUE,"")} -> J_H2A | F39: 8 | G39: =IF(E39<>"",E39&"_"&F39,"") -> J_H2A_8
A40: 01/24 07:01:00 | B40: 【今日の人工衛星】1/24 1990年：MUSES-A[ひてん] 工学実験衛星、M-3SII 5号機で20:46打ち上げ。初のエアロブレーキ実験に成功、日本がスウィングバイを含め衛星を自由に操る技術を習得することができた。 | C40: =LEN(B40) -> 111 | D40: n012402d | E40: {=_xlfn.IFS(IFERROR(FIND("M-3SII",B40),-1)>0,"J_M3S2",IFERROR(FIND("M-V",B40),-1)>0,"J_M5",IFERROR(FIND("M-4S",B40),-1)>0,"J_M4S",IFERROR(FIND("M-3C",B40),-1)>0,"J_M3C",IFERROR(FIND("M-3S",B40),-1)>0,"J_M3S",IFERROR(FIND("M-3H",B40),-1)>0,"J_M3H",IFERROR(FIND("H-IIA",B40),-1)>0,"J_H2A",IFERROR(FIND("H-IIB",B40),-1)>0,"J_H2B",IFERROR(FIND("H-II",B40),-1)>0,"J_H2",IFERROR(FIND("H-I",B40),-1)>0,"J_H1",IFERROR(FIND("N-II",B40),-1)>0,"J_N2",IFERROR(FIND("N-I",B40),-1)>0,"J_N1",IFERROR(FIND("イプシロン",B40),-1)>0,"J_E",TRUE,"")} -> J_M3S2 | F40: 5 | G40: =IF(E40<>"",E40&"_"&F40,"") -> J_M3S2_5
...

Sheet データチェック
P1: 行ラベル | Q1: 個数 / Number
P2: n010101d | Q2: 1
B3: Rocket_type | C3: Rocket_number | D3: desc | E3: exist | F3: cnt | G3: text | I3: Rocket_type | J3: Rocket_number | K3: desc | L3: exist | M3: cnt | N3: text | P3: n010201d | Q3: 1
B4: J_N1 | C4: 1 | E4: =IF(F4>=2,"◯",IF(F4>0,"△","✕")) -> ◯ | F4: =COUNTIFS(todayssatellite!$E:$E,データチェック!B4,todayssatellite!$F:$F,データチェック!C4) -> 2 | G4: =OFFSET(todayssatellite!$B$1,MATCH(B4&"_"&C4,todayssatellite!$G:$G,0)-1,0) -> 【今日の人工衛星】9/9 (14:30打上) 1975年：きく1号 宇宙開発事業団(NASDA)初の人工衛星。N-Iロケット1号機で打上。人工衛星の軌道投入、通信、姿勢制御等の技術習得が目的。実験は無事成功した。 | I4: J_L4S | J4: 5 | L4: =IF(M4>=2,"◯",IF(M4>0,"△","✕")) -> ◯ | M4: =COUNTIFS(todayssatellite!$E:$E,データチェック!I4,todayssatellite!$F:$F,データチェック!J4) -> 2 | N4: =OFFSET(todayssatellite!$B$1,MATCH(I4&"_"&J4,todayssatellite!$G:$G,0)-1,0) -> 【今日の人工衛星】2/11 1970年：おおすみ 日本初の人工衛星。世界で4番目に自力打ち上げに成功した。 1992年：ふよう 地球資源衛星。日本初の合成開口レーダー搭載衛星。6年間活動した。 | P4: n010301d | Q4: 1
B5: J_N1 | C5: 2 | E5: =IF(F5>=2,"◯",IF(F5>0,"△","✕")) -> ◯ | F5: =COUNTIFS(todayssatellite!$E:$E,データチェック!B5,todayssatellite!$F:$F,データチェック!C5) -> 2 | G5: =OFFSET(todayssatellite!$B$1,MATCH(B5&"_"&C5,todayssatellite!$G:$G,0)-1,0) -> 【今日の人工衛星】2/29 1976年：うめ 電離層観測を実施、世界で初めて電離層臨界周波数の地球周回分布を明らかにしたが、約1ヶ月で機能しなくなってしまった。 | I5: J_M4S | J5: 1 | K5: 失敗 | L5: =IF(M5>=2,"◯",IF(M5>0,"△","✕")) -> ✕ | M5: =COUNTIFS(todayssatellite!$E:$E,データチェック!I5,todayssatellite!$F:$F,データチェック!J5) -> 0 | N5: =OFFSET(todayssatellite!$B$1,MATCH(I5&"_"&J5,todayssatellite!$G:$G,0)-1,0) -> #N/A | P5: n010401d | Q5: 1
B6: J_N1 | C6: 3 | E6: =IF(F6>=2,"◯",IF(F6>0,"△","✕")) -> ◯ | F6: =COUNTIFS(todayssatellite!$E:$E,データチェック!B6,todayssatellite!$F:$F,データチェック!C6) -> 2 | G6: =OFFSET(todayssatellite!$B$1,MATCH(B6&"_"&C6,todayssatellite!$G:$G,0)-1,0) -> 【今日の人工衛星】2/23 1977年：きく2号 日本初の静止衛星。きくシリーズは技術試験衛星。 | I6: J_M4S | J6: 2 | L6: =IF(M6>=2,"◯",IF(M6>0,"△","✕")) -> ◯ | M6: =COUNTIFS(todayssatellite!$E:$E,データチェック!I6,todayssatellite!$F:$F,データチェック!J6) -> 2 | N6: =OFFSET(todayssatellite!$B$1,MATCH(I6&"_"&J6,todayssatellite!$G:$G,0)-1,0) -> 【今日の人工衛星】2/16 1971年：たんせい1号 Muロケット初の衛星、ロケットの性能確認が主目的。名前の由来は東大のスクールカラーの「淡青」。 1974年：たんせい2号 衛星制御システムの試験を目的とした衛星 | P6: n010501d | Q6: 1
B7: J_N1 | C7: 4 | E7: =IF(F7>=2,"◯",IF(F7>0,"△","✕")) -> ✕ | F7: =COUNTIFS(todayssatellite!$E:$E,データチェック!B7,todayssatellite!$F:$F,データチェック!C7) -> 0 | G7: =OFFSET(todayssatellite!$B$1,MATCH(B7&"_"&C7,todayssatellite!$G:$G,0)-1,0) -> #N/A | I7: J_M4S | J7: 3 | L7: =IF(M7>=2,"◯",IF(M7>0,"△","✕")) -> ◯ | M7: =COUNTIFS(todayssatellite!$E:$E,データチェック!I7,todayssatellite!$F:$F,データチェック!J7) -> 2 | N7: =OFFSET(todayssatellite!$B$1,MATCH(I7&"_"&J7,todayssatellite!$G:$G,0)-1,0) -> 【今日の人工衛星】9/28 1971年：しんせい M-4Sロケット3号機で打ち上げた日本初の科学衛星（おおすみ、たんせいは試験衛星）であり、初めての本格的な人工衛星である | P7: n010601d | Q7: 1
B8: J_N1 | C8: 5 | E8: =IF(F8>=2,"◯",IF(F8>0,"△","✕")) -> ◯ | F8: =COUNTIFS(todayssatellite!$E:$E,データチェック!B8,todayssatellite!$F:$F,データチェック!C8) -> 2 | G8: =OFFSET(todayssatellite!$B$1,MATCH(B8&"_"&C8,todayssatellite!$G:$G,0)-1,0) -> 【今日の人工衛星】2/6 1979年：あやめ1号 N-I 5号機で打ち上げ、静止衛星軌道への投入失敗。日本のかつての苦労が偲ばれます。 | I8: J_M4S | J8: 4 | L8: =IF(M8>=2,"◯",IF(M8>0,"△","✕")) -> ◯ | M8: =COUNTIFS(todayssatellite!$E:$E,データチェック!I8,todayssatellite!$F:$F,データチェック!J8) -> 2 | N8: =OFFSET(todayssatellite!$B$1,MATCH(I8&"_"&J8,todayssatellite!$G:$G,0)-1,0) -> 【今日の人工衛星】8/19 1972年：でんぱ(REXS) 電離層・磁気圏観測衛星。打上時のランチャーの角度のズレにより予定と大きく異なる軌道に投入。70時間で故障したが、その軌道により高層大気密度のデータ収集が可能に | P8: n010701d | Q8: 1
B9: J_N1 | C9: 6 | E9: =IF(F9>=2,"◯",IF(F9>0,"△","✕")) -> ◯ | F9: =COUNTIFS(todayssatellite!$E:$E,データチェック!B9,todayssatellite!$F:$F,データチェック!C9) -> 2 | G9: =OFFSET(todayssatellite!$B$1,MATCH(B9&"_"&C9,todayssatellite!$G:$G,0)-1,0) -> 【今日の人工衛星】2/22 1980年：あやめ2号 実験用静止通信衛星、失敗したあやめ1号の予備衛星だが、アポジモーターの不具合により衛星軌道への投入は失敗。 1986年：Viking スウェーデンの最初の衛星。 | I9: J_M3C | J9: 1 | L9: =IF(M9>=2,"◯",IF(M9>0,"△","✕")) -> △ | M9: =COUNTIFS(todayssatellite!$E:$E,データチェック!I9,todayssatellite!$F:$F,データチェック!J9) -> 1 | N9: =OFFSET(todayssatellite!$B$1,MATCH(I9&"_"&J9,todayssatellite!$G:$G,0)-1,0) -> ★1974年の今日2/16 14:00、M-3Cロケット1号機でたんせい2号が打ち上げられました。 | P9: n010801d | Q9: 1
B10: J_N1 | C10: 7 | E10: =IF(F10>=2,"◯",IF(F10>0,"△","✕")) -> ◯ | F10: =COUNTIFS(todayssatellite!$E:$E,データチェック!B10,todayssatellite!$F:$F,データチェック!C10) -> 2 | G10: =OFFSET(todayssatellite!$B$1,MATCH(B10&"_"&C10,todayssatellite!$G:$G,0)-1,0) -> 【今日の人工衛星】9/3 (14:00打上) 1982年：きく4号 N-Iロケット7号機で打上。三軸制御、太陽電池パドルの展開、能動式熱制御などの技術試験・確認が目的で、実験は成功した | I10: J_M3C | J10: 2 | L10: =IF(M10>=2,"◯",IF(M10>0,"△","✕")) -> ✕ | M10: =COUNTIFS(todayssatellite!$E:$E,データチェック!I10,todayssatellite!$F:$F,データチェック!J10) -> 0 | N10: =OFFSET(todayssatellite!$B$1,MATCH(I10&"_"&J10,todayssatellite!$G:$G,0)-1,0) -> #N/A | P10: n010801t1 | Q10: 1
B11: J_N2 | C11: 1 | E11: =IF(F11>=2,"◯",IF(F11>0,"△","✕")) -> ◯ | F11: =COUNTIFS(todayssatellite!$E:$E,データチェック!B11,todayssatellite!$F:$F,データチェック!C11) -> 4 | G11: =OFFSET(todayssatellite!$B$1,MATCH(B11&"_"&C11,todayssatellite!$G:$G,0)-1,0) -> 【今日の人工衛星】2/11 1981年：きく3号 N-IIロケットの静止トランスファ軌道投入性能の確認、大型衛星の開発技術の習得を目的とした。ETS-IVであるがETS-IIIと打上順序が入れ替わったため、打上順につけられた愛称は3号となっている | I11: J_M3C | J11: 3 | K11: 失敗 | L11: =IF(M11>=2,"◯",IF(M11>0,"△","✕")) -> ✕ | M11: =COUNTIFS(todayssatellite!$E:$E,データチェック!I11,todayssatellite!$F:$F,データチェック!J11) -> 0 | N11: =OFFSET(todayssatellite!$B$1,MATCH(I11&"_"&J11,todayssatellite!$G:$G,0)-1,0) -> #N/A | P11: n010901d | Q11: 1
B12: J_N2 | C12: 2 | E12: =IF(F12>=2,"◯",IF(F12>0,"△","✕")) -> ✕ | F12: =COUNTIFS(todayssatellite!$E:$E,データチェック!B12,todayssatellite!$F:$F,データチェック!C12) -> 0 | G12: =OFFSET(todayssatellite!$B$1,MATCH(B12&"_"&C12,todayssatellite!$G:$G,0)-1,0) -> #N/A | I12: J_M3C | J12: 4 | L12: =IF(M12>=2,"◯",IF(M12>0,"△","✕")) -> ◯ | M12: =COUNTIFS(todayssatellite!$E:$E,データチェック!I12,todayssatellite!$F:$F,データチェック!J12) -> 2 | N12: =OFFSET(todayssatellite!$B$1,MATCH(I12&"_"&J12,todayssatellite!$G:$G,0)-1,0) -> 【今日の人工衛星】2/21 1979年：はくちょう 日本初のX線天文衛星。打ち上げ失敗したCORSAを3年で作り直して打ち上げたもの。 1981年：ひのとり 日本初の太陽観測衛星。命名は手塚治虫の同名漫画による。約10年間運用された。 | P12: n011001d | Q12: 1
B13: J_N2 | C13: 3 | E13: =IF(F13>=2,"◯",IF(F13>0,"△","✕")) -> ✕ | F13: =COUNTIFS(todayssatellite!$E:$E,データチェック!B13,todayssatellite!$F:$F,データチェック!C13) -> 0 | G13: =OFFSET(todayssatellite!$B$1,MATCH(B13&"_"&C13,todayssatellite!$G:$G,0)-1,0) -> #N/A | I13: J_M3H | J13: 1 | L13: =IF(M13>=2,"◯",IF(M13>0,"△","✕")) -> ◯ | M13: =COUNTIFS(todayssatellite!$E:$E,データチェック!I13,todayssatellite!$F:$F,データチェック!J13) -> 2 | N13: =OFFSET(todayssatellite!$B$1,MATCH(I13&"_"&J13,todayssatellite!$G:$G,0)-1,0) -> 【今日の人工衛星】2/19 1977年：たんせい3号 M-3Hロケットの試験、姿勢制御を実験。ヒートパイプや、誤作動が発生したが、これが後の衛星に活かされている 1988年：さくら3a号 実験用通信衛星さくらの3代目 | P13: n011101d | Q13: 1
B14: J_N2 | C14: 4 | E14: =IF(F14>=2,"◯",IF(F14>0,"△","✕")) -> ◯ | F14: =COUNTIFS(todayssatellite!$E:$E,データチェック!B14,todayssatellite!$F:$F,データチェック!C14) -> 2 | G14: =OFFSET(todayssatellite!$B$1,MATCH(B14&"_"&C14,todayssatellite!$G:$G,0)-1,0) -> 【今日の人工衛星】8/5(UTC) 1983年：さくら2号b 日本の通信衛星。日本時間8月6日にN-IIロケット4号機で打ち上げ。1990年に運用終了。 | I14: J_M3H | J14: 2 | L14: =IF(M14>=2,"◯",IF(M14>0,"△","✕")) -> ◯ | M14: =COUNTIFS(todayssatellite!$E:$E,データチェック!I14,todayssatellite!$F:$F,データチェック!J14) -> 2 | N14: =OFFSET(todayssatellite!$B$1,MATCH(I14&"_"&J14,todayssatellite!$G:$G,0)-1,0) -> 【今日の人工衛星】2/4 2002年：DASH[高速再突入実験機]・つばさ[民生部品・コンポーネント実証衛星] H-IIA 2号機、 1978年：EXOS-A[きょっこう]オーロラ観測、M-3H 2号機 1983年：さくら2A 静止通信衛星、N-II 3号機 | P14: n011201d | Q14: 1
B15: J_N2 | C15: 5 | E15: =IF(F15>=2,"◯",IF(F15>0,"△","✕")) -> ✕ | F15: =COUNTIFS(todayssatellite!$E:$E,データチェック!B15,todayssatellite!$F:$F,データチェック!C15) -> 0 | G15: =OFFSET(todayssatellite!$B$1,MATCH(B15&"_"&C15,todayssatellite!$G:$G,0)-1,0) -> #N/A | I15: J_M3H | J15: 3 | L15: =IF(M15>=2,"◯",IF(M15>0,"△","✕")) -> ◯ | M15: =COUNTIFS(todayssatellite!$E:$E,データチェック!I15,todayssatellite!$F:$F,データチェック!J15) -> 2 | N15: =OFFSET(todayssatellite!$B$1,MATCH(I15&"_"&J15,todayssatellite!$G:$G,0)-1,0) -> 【今日の人工衛星】9/16 (14:00打上) 1978年：じきけん プラズマ・磁気圏観測衛星。M-3Hロケット3号機で打上。近地点227km、遠地点30,051kmという長楕円軌道で60mアンテナを用い観測を実施 | P15: n011301d | Q15: 1
B16: J_N2 | C16: 6 | E16: =IF(F16>=2,"◯",IF(F16>0,"△","✕")) -> ◯ | F16: =COUNTIFS(todayssatellite!$E:$E,データチェック!B16,todayssatellite!$F:$F,データチェック!C16) -> 2 | G16: =OFFSET(todayssatellite!$B$1,MATCH(B16&"_"&C16,todayssatellite!$G:$G,0)-1,0) -> 【今日の人工衛星】8/2(UTC) 1984年：ひまわり3号 日本の気象衛星。日本時間8/3に種子島からN-IIロケット6号機で打ち上げ。ひまわり2号の不調をカバーするため少し早く打ち上げられた | I16: J_M3S | J16: 1 | L16: =IF(M16>=2,"◯",IF(M16>0,"△","✕")) -> ◯ | M16: =COUNTIFS(todayssatellite!$E:$E,データチェック!I16,todayssatellite!$F:$F,データチェック!J16) -> 2 | N16: =OFFSET(todayssatellite!$B$1,MATCH(I16&"_"&J16,todayssatellite!$G:$G,0)-1,0) -> 【今日の人工衛星】2/17 1980年：たんせい4号 M-3Sロケットの打ち上げ性能試験、及び後続の科学衛星で使われる様々な技術の試験が目的。 | P16: n011401d | Q16: 1
B17: J_N2 | C17: 7 | E17: =IF(F17>=2,"◯",IF(F17>0,"△","✕")) -> ✕ | F17: =COUNTIFS(todayssatellite!$E:$E,データチェック!B17,todayssatellite!$F:$F,データチェック!C17) -> 0 | G17: =OFFSET(todayssatellite!$B$1,MATCH(B17&"_"&C17,todayssatellite!$G:$G,0)-1,0) -> #N/A | I17: J_M3S | J17: 2 | L17: =IF(M17>=2,"◯",IF(M17>0,"△","✕")) -> △ | M17: =COUNTIFS(todayssatellite!$E:$E,データチェック!I17,todayssatellite!$F:$F,データチェック!J17) -> 1 | N17: =OFFSET(todayssatellite!$B$1,MATCH(I17&"_"&J17,todayssatellite!$G:$G,0)-1,0) -> ★1981年の今日2/21 9:30、M-3Sロケット2号機で太陽観測衛星ひのとりが打ち上げられました。 | P17: n011501d | Q17: 1
B18: J_N2 | C18: 8 | E18: =IF(F18>=2,"◯",IF(F18>0,"△","✕")) -> △ | F18: =COUNTIFS(todayssatellite!$E:$E,データチェック!B18,todayssatellite!$F:$F,データチェック!C18) -> 1 | G18: =OFFSET(todayssatellite!$B$1,MATCH(B18&"_"&C18,todayssatellite!$G:$G,0)-1,0) -> 【今日の人工衛星】2/19 1987年：もも1号 海洋観測衛星。N-IIロケット8号機で打上。日本初の地球観測衛星である。 | I18: J_M3S | J18: 3 | L18: =IF(M18>=2,"◯",IF(M18>0,"△","✕")) -> ◯ | M18: =COUNTIFS(todayssatellite!$E:$E,データチェック!I18,todayssatellite!$F:$F,データチェック!J18) -> 2 | N18: =OFFSET(todayssatellite!$B$1,MATCH(I18&"_"&J18,todayssatellite!$G:$G,0)-1,0) -> 【今日の人工衛星】2/20 1983年：てんま ISASのX線天文衛星2代目。観測運用は2年半にとどまった。 2001年：Odin スウェーデンのサブミリ波観測衛星。酸素分子からなる星間雲の存在を初めて発見。 | P18: n011502d | Q18: 1
B19: J_H1 | C19: 1 | E19: =IF(F19>=2,"◯",IF(F19>0,"△","✕")) -> ◯ | F19: =COUNTIFS(todayssatellite!$E:$E,データチェック!B19,todayssatellite!$F:$F,データチェック!C19) -> 3 | G19: =OFFSET(todayssatellite!$B$1,MATCH(B19&"_"&C19,todayssatellite!$G:$G,0)-1,0) -> 【今日の人工衛星】8/12(UTC) 1986年：あじさい(EGS) H-Iロケット初号機で打ち上げられた測地実験衛星。打ち上げから25年経つ2011年現在も運用中 | I19: J_M3S | J19: 4 | L19: =IF(M19>=2,"◯",IF(M19>0,"△","✕")) -> ✕ | M19: =COUNTIFS(todayssatellite!$E:$E,データチェック!I19,todayssatellite!$F:$F,データチェック!J19) -> 0 | N19: =OFFSET(todayssatellite!$B$1,MATCH(I19&"_"&J19,todayssatellite!$G:$G,0)-1,0) -> #N/A | P19: n011502t1 | Q19: 1
B20: J_H1 | C20: 2 | E20: =IF(F20>=2,"◯",IF(F20>0,"△","✕")) -> ◯ | F20: =COUNTIFS(todayssatellite!$E:$E,データチェック!B20,todayssatellite!$F:$F,データチェック!C20) -> 2 | G20: =OFFSET(todayssatellite!$B$1,MATCH(B20&"_"&C20,todayssatellite!$G:$G,0)-1,0) -> 【今日の人工衛星】8/27 (18:20打上) 1987年：きく5号 H-Iロケット試験機2号機の性能確認と、移動体通信実験のための衛星。静止3軸衛星バスの基盤技術を確立。 | I20: J_M3S2 | J20: 1 | L20: =IF(M20>=2,"◯",IF(M20>0,"△","✕")) -> ◯ | M20: =COUNTIFS(todayssatellite!$E:$E,データチェック!I20,todayssatellite!$F:$F,データチェック!J20) -> 2 | N20: =OFFSET(todayssatellite!$B$1,MATCH(I20&"_"&J20,todayssatellite!$G:$G,0)-1,0) -> 【今日の人工衛星】1/8 1985年：さきがけ 日本のハレー彗星探査機。8/19に打ち上げられた「すいせい」の姉妹機にあたり、さきがけでの経験が「すいせい」にフィードバックされた。 | P20: n011601d | Q20: 1
B21: J_H1 | C21: 3 | E21: =IF(F21>=2,"◯",IF(F21>0,"△","✕")) -> ✕ | F21: =COUNTIFS(todayssatellite!$E:$E,データチェック!B21,todayssatellite!$F:$F,データチェック!C21) -> 0 | G21: =OFFSET(todayssatellite!$B$1,MATCH(B21&"_"&C21,todayssatellite!$G:$G,0)-1,0) -> #N/A | I21: J_M3S2 | J21: 2 | L21: =IF(M21>=2,"◯",IF(M21>0,"△","✕")) -> ◯ | M21: =COUNTIFS(todayssatellite!$E:$E,データチェック!I21,todayssatellite!$F:$F,データチェック!J21) -> 2 | N21: =OFFSET(todayssatellite!$B$1,MATCH(I21&"_"&J21,todayssatellite!$G:$G,0)-1,0) -> 【今日の人工衛星】8/18(UTC) 1985年：すいせい ハレー彗星観測を目的とした2機目の宇宙探査機。ハレー彗星からの塵で2回姿勢を乱すも無事に観測を完了 | P21: n011701d | Q21: 1
B22: J_H1 | C22: 4 | E22: =IF(F22>=2,"◯",IF(F22>0,"△","✕")) -> ◯ | F22: =COUNTIFS(todayssatellite!$E:$E,データチェック!B22,todayssatellite!$F:$F,データチェック!C22) -> 2 | G22: =OFFSET(todayssatellite!$B$1,MATCH(B22&"_"&C22,todayssatellite!$G:$G,0)-1,0) -> 【今日の人工衛星】9/16 (18:59打上) 1988年：さくら3号b H-Iロケット4号機で打ち上げられた通信衛星。実験衛星としては3bが最後で、この後は民間の実用衛星が打ち上げられる(1989年のJCSAT～) | I22: J_M3S2 | J22: 3 | L22: =IF(M22>=2,"◯",IF(M22>0,"△","✕")) -> ◯ | M22: =COUNTIFS(todayssatellite!$E:$E,データチェック!I22,todayssatellite!$F:$F,データチェック!J22) -> 2 | N22: =OFFSET(todayssatellite!$B$1,MATCH(I22&"_"&J22,todayssatellite!$G:$G,0)-1,0) -> 【今日の人工衛星】2/5 1987年：ASTRO-C[ぎんが]X線天文衛星、M-3SII 3号機で打ち上げ。超新星1987Aの観測に成功。1991年11月1日に大気圏に突入し消滅。 | P22: n011801d | Q22: 1
B23: J_H1 | C23: 5 | E23: =IF(F23>=2,"◯",IF(F23>0,"△","✕")) -> ◯ | F23: =COUNTIFS(todayssatellite!$E:$E,データチェック!B23,todayssatellite!$F:$F,データチェック!C23) -> 2 | G23: =OFFSET(todayssatellite!$B$1,MATCH(B23&"_"&C23,todayssatellite!$G:$G,0)-1,0) -> 【今日の人工衛星】9/5(UTC) (日本時間6日4:11打上) 1989年：ひまわり4号。 気象観測衛星。大きなトラブルもなく、順調に運用され、2002年2月に運用終了。 | I23: J_M3S2 | J23: 4 | L23: =IF(M23>=2,"◯",IF(M23>0,"△","✕")) -> ◯ | M23: =COUNTIFS(todayssatellite!$E:$E,データチェック!I23,todayssatellite!$F:$F,データチェック!J23) -> 2 | N23: =OFFSET(todayssatellite!$B$1,MATCH(I23&"_"&J23,todayssatellite!$G:$G,0)-1,0) -> 【今日の人工衛星】2/21(UTC、日本時間翌22日8:30) 1989年：あけぼの 地球磁気圏観測衛星、設計寿命の1年を大きく越えて、2015年4月23日まで26年間運用された。太陽活動周期2周期(22年)分の観測も達成した。 | P23: n011901d | Q23: 1
... B26: J_H1 | C26: 8 | E26: =IF(F26>=2,"◯",IF(F26>0,"△","✕")) -> ◯ | F26: =COUNTIFS(todayssatellite!$E:$E,データチェック!B26,todayssatellite!$F:$F,データチェック!C26) -> 2 | G26: =OFFSET(todayssatellite!$B$1,MATCH(B26&"_"&C26,todayssatellite!$G:$G,0)-1,0) -> 【今日の人工衛星】8/25 1991年：ゆり3号b 日本の放送衛星。H-Iロケット8号機で打ち上げられ、ゆり3号aの太陽電池不具合による出力不足を補った。現時点で、種子島から打ち上げた最後の放送衛星。1998年運用停止 | I26: J_M3S2 | J26: 7 | L26: =IF(M26>=2,"◯",IF(M26>0,"△","✕")) -> ◯ | M26: =COUNTIFS(todayssatellite!$E:$E,データチェック!I26,todayssatellite!$F:$F,データチェック!J26) -> 2 | N26: =OFFSET(todayssatellite!$B$1,MATCH(I26&"_"&J26,todayssatellite!$G:$G,0)-1,0) -> 【今日の人工衛星】2/20 1993年：あすか 宇宙X線観測衛星。M-3SIIロケット7号機で打上。2000年7月14日の太陽フレアによる地球大気膨張の影響で姿勢が乱れ観測不能に。2001年3月2日に大気圏に突入、消滅した。 | P26: n012201d | Q26: 1
B27: J_H1 | C27: 9 | E27: =IF(F27>=2,"◯",IF(F27>0,"△","✕")) -> △ | F27: =COUNTIFS(todayssatellite!$E:$E,データチェック!B27,todayssatellite!$F:$F,データチェック!C27) -> 1 | G27: =OFFSET(todayssatellite!$B$1,MATCH(B27&"_"&C27,todayssatellite!$G:$G,0)-1,0) -> ★1992年の今日2/11 10:50、H-Iロケット9号機で地球観測衛星ふよう1号が打ち上げられました。 | I27: J_M3S2 | J27: 8 | K27: 失敗 | L27: =IF(M27>=2,"◯",IF(M27>0,"△","✕")) -> ◯ | M27: =COUNTIFS(todayssatellite!$E:$E,データチェック!I27,todayssatellite!$F:$F,データチェック!J27) -> 2 | N27: =OFFSET(todayssatellite!$B$1,MATCH(I27&"_"&J27,todayssatellite!$G:$G,0)-1,0) -> 【今日の人工衛星】1/15 1995年：自立帰還型無人宇宙実験システム(EXPRESS) M-3SIIロケット8号機で打上。軌道再突入試験を目的としていたが実験は失敗。機体はガーナに着陸しており、翌年回収された。 | P27: n012201t1 | Q27: 1
B28: J_H2 | C28: 1 | E28: =IF(F28>=2,"◯",IF(F28>0,"△","✕")) -> ◯ | F28: =COUNTIFS(todayssatellite!$E:$E,データチェック!B28,todayssatellite!$F:$F,データチェック!C28) -> 2 | G28: =OFFSET(todayssatellite!$B$1,MATCH(B28&"_"&C28,todayssatellite!$G:$G,0)-1,0) -> 【今日の人工衛星】2/3(UTC) 1994年：VEP[みょうじょう]H-IIロケット性能確認用ペイロード、OREX[りゅうせい]大気圏再突入実験衛星、H-II 1号機で打ち上げ | I28: J_M5 | J28: 1 | L28: =IF(M28>=2,"◯",IF(M28>0,"△","✕")) -> ◯ | M28: =COUNTIFS(todayssatellite!$E:$E,データチェック!I28,todayssatellite!$F:$F,データチェック!J28) -> 2 | N28: =OFFSET(todayssatellite!$B$1,MATCH(I28&"_"&J28,todayssatellite!$G:$G,0)-1,0) -> 【今日の人工衛星】2/12 1997年：はるか(MUSES-B) 電波天文衛星。M-Vロケット初号機で打上。地上の電波望遠鏡と連携して巨大な電波望遠鏡と同等の性能を出すVLBIの宇宙側の望遠鏡として打上られ、スペースVLBIを実現した。 | P28: n012301d | Q28: 1
B29: J_H2 | C29: 2 | E29: =IF(F29>=2,"◯",IF(F29>0,"△","✕")) -> ◯ | F29: =COUNTIFS(todayssatellite!$E:$E,データチェック!B29,todayssatellite!$F:$F,データチェック!C29) -> 2 | G29: =OFFSET(todayssatellite!$B$1,MATCH(B29&"_"&C29,todayssatellite!$G:$G,0)-1,0) -> 【今日の人工衛星】8/28 (16:50打上) 1994年：きく6号 H-IIロケット試験機2号機により打上。アポジエンジンの不具合により静止軌道投入は出来なかったが、多くの実験は実施された。 | I29: J_M5 | J29: 2 | K29: 欠番 | P29: n012302d | Q29: 1
B30: J_H2 | C30: 3 | E30: =IF(F30>=2,"◯",IF(F30>0,"△","✕")) -> ◯ | F30: =COUNTIFS(todayssatellite!$E:$E,データチェック!B30,todayssatellite!$F:$F,データチェック!C30) -> 2 | G30: =OFFSET(todayssatellite!$B$1,MATCH(B30&"_"&C30,todayssatellite!$G:$G,0)-1,0) -> 【今日の人工衛星】3/18 1995年：ひまわり5号＋SFU H-IIロケット3号機で打ち上げ。ひまわり5号は、のちのMTSAT-1打ち上げ失敗などにより設計寿命の倍、10年間働くことになる。SFUはスペースシャトルミッションSTS-72で若田飛行士により回収、地球に帰還する。 | I30: J_M5 | J30: 3 | L30: =IF(M30>=2,"◯",IF(M30>0,"△","✕")) -> ◯ | M30: =COUNTIFS(todayssatellite!$E:$E,データチェック!I30,todayssatellite!$F:$F,データチェック!J30) -> 2 | N30: =OFFSET(todayssatellite!$B$1,MATCH(I30&"_"&J30,todayssatellite!$G:$G,0)-1,0) -> 【今日の人工衛星】7/3(UTC) 1998年：のぞみ 火星探査機。月の裏側を撮影、旧ソ連・米国に次ぎ3番目となる。度重なる故障、月で2回、地球で3回のスイングバイを経て火星近くに到達するも軌道投入はかなわず | P30: n012302t1 | Q30: 1
B31: J_H2 | C31: 4 | E31: =IF(F31>=2,"◯",IF(F31>0,"△","✕")) -> ◯ | F31: =COUNTIFS(todayssatellite!$E:$E,データチェック!B31,todayssatellite!$F:$F,データチェック!C31) -> 2 | G31: =OFFSET(todayssatellite!$B$1,MATCH(B31&"_"&C31,todayssatellite!$G:$G,0)-1,0) -> 【今日の人工衛星】8/17 1996年：みどり(ADEOS) 地球観測プラットフォーム衛星。大気・海洋・陸域観測結果の成果は大きかったが、太陽電池パドルのブランケットが破断し10ヶ月で運用停止。 | I31: J_M5 | J31: 4 | K31: 失敗 | L31: =IF(M31>=2,"◯",IF(M31>0,"△","✕")) -> ◯ | M31: =COUNTIFS(todayssatellite!$E:$E,データチェック!I31,todayssatellite!$F:$F,データチェック!J31) -> 2 | N31: =OFFSET(todayssatellite!$B$1,MATCH(I31&"_"&J31,todayssatellite!$G:$G,0)-1,0) -> 【今日の人工衛星】2/10 2000年：ASTRO-E X線天文衛星。M-Vロケット4号機で打ち上げたが、1段目のノズル破損により速度不足となり、打上に失敗した。 | P31: n012302t2 | Q31: 1
B32: J_H2 | C32: 5 | E32: =IF(F32>=2,"◯",IF(F32>0,"△","✕")) -> ◯ | F32: =COUNTIFS(todayssatellite!$E:$E,データチェック!B32,todayssatellite!$F:$F,データチェック!C32) -> 2 | G32: =OFFSET(todayssatellite!$B$1,MATCH(B32&"_"&C32,todayssatellite!$G:$G,0)-1,0) -> 【今日の人工衛星】2/21 1998年：かけはし 通信放送技術衛星。移動体通信の実験が目的。H-IIロケット5号機で打上られたが、2段目の燃焼が短く、静止軌道への投入は失敗した。低軌道でも行える実験は実施された。 | I32: J_M5 | J32: 5 | L32: =IF(M32>=2,"◯",IF(M32>0,"△","✕")) -> ◯ | M32: =COUNTIFS(todayssatellite!$E:$E,データチェック!I32,todayssatellite!$F:$F,データチェック!J32) -> 7 | N32: =OFFSET(todayssatellite!$B$1,MATCH(I32&"_"&J32,todayssatellite!$G:$G,0)-1,0) -> 【今日の人工衛星】5/9 2003年：はやぶさ（MUSES-C） 小惑星探査機、工学実験機。小惑星1998-SF36(打ち上げ後にイトカワと命名)との往復、サンプルリターンに成功。2010年6月13日に地球に帰還。 | P32: n012302t3 | Q32: 1
B33: J_H2 | C33: 6 | E33: =IF(F33>=2,"◯",IF(F33>0,"△","✕")) -> ◯ | F33: =COUNTIFS(todayssatellite!$E:$E,データチェック!B33,todayssatellite!$F:$F,データチェック!C33) -> 3 | G33: =OFFSET(todayssatellite!$B$1,MATCH(B33&"_"&C33,todayssatellite!$G:$G,0)-1,0) -> 【今日の人工衛星】11/27(UTC,日本時間28日6:27) 1997年：きく7号(おりひめ・ひこぼし) 軌道上での人工衛星の自動ランデブー・ドッキング技術を習得した衛星。この技術は後にHTV(こうのとり)にも活用、高い評価を得た。 | I33: J_M5 | J33: 6 | L33: =IF(M33>=2,"◯",IF(M33>0,"△","✕")) -> ◯ | M33: =COUNTIFS(todayssatellite!$E:$E,データチェック!I33,todayssatellite!$F:$F,データチェック!J33) -> 2 | N33: =OFFSET(todayssatellite!$B$1,MATCH(I33&"_"&J33,todayssatellite!$G:$G,0)-1,0) -> 【今日の人工衛星】7/10 2005年：すざく あすかに続く5機目の日本のX線天文衛星であり、2000年に打ち上げ失敗したASTRO-Eの代替機。液体ヘリウム喪失事故があったものの、2015年6月まで運用は継続された。2025年1月に大気圏再突入。 | P33: n012302t4 | Q33: 1
B34: J_H2 | C34: 7 | D34: 欠番 | I34: J_M5 | J34: 7 | L34: =IF(M34>=2,"◯",IF(M34>0,"△","✕")) -> ◯ | M34: =COUNTIFS(todayssatellite!$E:$E,データチェック!I34,todayssatellite!$F:$F,データチェック!J34) -> 4 | N34: =OFFSET(todayssatellite!$B$1,MATCH(I34&"_"&J34,todayssatellite!$G:$G,0)-1,0) -> 【今日の人工衛星】9/22(UTC、日本時間23日6:36打上) 2006年：ひので 太陽観測衛星。M-Vロケット7号機で打上（M-V最後の打上）。他の衛星に比べ非常に高い分解能で太陽を精密に観測できる | P34: n012302t5 | Q34: 1
B35: J_H2 | C35: 8 | E35: =IF(F35>=2,"◯",IF(F35>0,"△","✕")) -> ◯ | F35: =COUNTIFS(todayssatellite!$E:$E,データチェック!B35,todayssatellite!$F:$F,データチェック!C35) -> 2 | G35: =OFFSET(todayssatellite!$B$1,MATCH(B35&"_"&C35,todayssatellite!$G:$G,0)-1,0) -> 【今日の人工衛星】11/15 1999年：みらい/H-IIロケット8号機 ひまわり5号の代替となる衛星となる予定だったが打上が失敗。LE-7エンジンは3000mの海底から回収・分析され、その経験は現行のLE-7Aエンジンに活かされている | I35: J_M5 | J35: 8 | L35: =IF(M35>=2,"◯",IF(M35>0,"△","✕")) -> ◯ | M35: =COUNTIFS(todayssatellite!$E:$E,データチェック!I35,todayssatellite!$F:$F,データチェック!J35) -> 4 | N35: =OFFSET(todayssatellite!$B$1,MATCH(I35&"_"&J35,todayssatellite!$G:$G,0)-1,0) -> 【今日の人工衛星】2/20(UTC、日本時間翌21日6:28) 2006年：あかり 赤外線天文衛星。赤外線観測のため望遠鏡を冷やす液体ヘリウムを搭載、消費し尽くす前に全天の94%の観測を完了した。バッテリーの劣化等のため、2011年11月24日に運用を終了した。 | P35: n012302t6 | Q35: 1
B36: J_H2A | C36: 1 | E36: =IF(F36>=2,"◯",IF(F36>0,"△","✕")) -> ◯ | F36: =COUNTIFS(todayssatellite!$E:$E,データチェック!B36,todayssatellite!$F:$F,データチェック!C36) -> 2 | G36: =OFFSET(todayssatellite!$B$1,MATCH(B36&"_"&C36,todayssatellite!$G:$G,0)-1,0) -> 【今日の人工衛星】8/29 (16:00打上) 2001年：H-IIAロケット試作機1号機 レーザ測距装置（LRE）と性能確認用ペイロード（VEP-2）を静止トランスファ軌道へ投入、試験は無事成功した | I36: J_E | J36: 1 | L36: =IF(M36>=2,"◯",IF(M36>0,"△","✕")) -> ◯ | M36: =COUNTIFS(todayssatellite!$E:$E,データチェック!I36,todayssatellite!$F:$F,データチェック!J36) -> 2 | N36: =OFFSET(todayssatellite!$B$1,MATCH(I36&"_"&J36,todayssatellite!$G:$G,0)-1,0) -> 【今日の人工衛星】9/14 (14:00打上) 2013年：ひさき 世界初の太陽系内惑星専用の宇宙望遠鏡。イプシロンロケットで打ち上げる小型科学衛星シリーズSPRINTの1号機にあたる。主に惑星の大気を観測。イプシロンロケットの初打上にもあたる | P36: n012302t7 | Q36: 1
B37: J_H2A | C37: 2 | E37: =IF(F37>=2,"◯",IF(F37>0,"△","✕")) -> △ | F37: =COUNTIFS(todayssatellite!$E:$E,データチェック!B37,todayssatellite!$F:$F,データチェック!C37) -> 1 | G37: =OFFSET(todayssatellite!$B$1,MATCH(B37&"_"&C37,todayssatellite!$G:$G,0)-1,0) -> ★2002年の今日2/4 11:45、H-IIAロケット2号機でDASH[高速再突入実験機]・つばさ[民生部品・コンポーネント実証衛星]が打ち上げられました。打上自体は成功しましたが、DASHはフェアリングからの分離に失敗しました。 | I37: J_E | J37: 2 | L37: =IF(M37>=2,"◯",IF(M37>0,"△","✕")) -> ✕ | M37: =COUNTIFS(todayssatellite!$E:$E,データチェック!I37,todayssatellite!$F:$F,データチェック!J37) -> 0 | N37: =OFFSET(todayssatellite!$B$1,MATCH(I37&"_"&J37,todayssatellite!$G:$G,0)-1,0) -> #N/A | P37: n012302t8 | Q37: 1
B38: J_H2A | C38: 3 | E38: =IF(F38>=2,"◯",IF(F38>0,"△","✕")) -> ◯ | F38: =COUNTIFS(todayssatellite!$E:$E,データチェック!B38,todayssatellite!$F:$F,データチェック!C38) -> 3 | G38: =OFFSET(todayssatellite!$B$1,MATCH(B38&"_"&C38,todayssatellite!$G:$G,0)-1,0) -> 【今日の人工衛星】9/10 (17:20打上) 2002年：USERS 無人の自律帰還型回収システムであり、軌道上で宇宙実験を行った結果を地上に持ち帰れるシステム。超電導材料製造実験を行い、無事サンプル回収に成功 | I38: J_E | J38: 3 | L38: =IF(M38>=2,"◯",IF(M38>0,"△","✕")) -> ✕ | M38: =COUNTIFS(todayssatellite!$E:$E,データチェック!I38,todayssatellite!$F:$F,データチェック!J38) -> 0 | N38: =OFFSET(todayssatellite!$B$1,MATCH(I38&"_"&J38,todayssatellite!$G:$G,0)-1,0) -> #N/A | P38: n012401d | Q38: 1
B39: J_H2A | C39: 4 | E39: =IF(F39>=2,"◯",IF(F39>0,"△","✕")) -> ◯ | F39: =COUNTIFS(todayssatellite!$E:$E,データチェック!B39,todayssatellite!$F:$F,データチェック!C39) -> 4 | G39: =OFFSET(todayssatellite!$B$1,MATCH(B39&"_"&C39,todayssatellite!$G:$G,0)-1,0) -> 【今日の人工衛星】12/14 2002年：みどりII 地球観測衛星。太陽電池パネル故障で通信途絶した「みどり」の後継機で、次世代のみどりとして「II」を名乗ったが、約1年で電源の不調により通信途絶。 | I39: J_E | J39: 4 | L39: =IF(M39>=2,"◯",IF(M39>0,"△","✕")) -> ✕ | M39: =COUNTIFS(todayssatellite!$E:$E,データチェック!I39,todayssatellite!$F:$F,データチェック!J39) -> 0 | N39: =OFFSET(todayssatellite!$B$1,MATCH(I39&"_"&J39,todayssatellite!$G:$G,0)-1,0) -> #N/A | P39: n012401t1 | Q39: 1
B40: J_H2A | C40: 5 | E40: =IF(F40>=2,"◯",IF(F40>0,"△","✕")) -> ◯ | F40: =COUNTIFS(todayssatellite!$E:$E,データチェック!B40,todayssatellite!$F:$F,データチェック!C40) -> 2 | G40: =OFFSET(todayssatellite!$B$1,MATCH(B40&"_"&C40,todayssatellite!$G:$G,0)-1,0) -> 【今日の人工衛星】3/28 2003年：情報収集衛星1号機(光学・レーダ) 日本初の偵察衛星。性能は光学が解像度1m程度と、民間衛星に比べても劣っていた。これ以降継続的に情報収集衛星が軌道上に打ち上げられることになる。 | I40: J_E | J40: 5 | L40: =IF(M40>=2,"◯",IF(M40>0,"△","✕")) -> ✕ | M40: =COUNTIFS(todayssatellite!$E:$E,データチェック!I40,todayssatellite!$F:$F,データチェック!J40) -> 0 | N40: =OFFSET(todayssatellite!$B$1,MATCH(I40&"_"&J40,todayssatellite!$G:$G,0)-1,0) -> #N/A | P40: n012402d | Q40: 1
B41: J_H2A | C41: 6 | D41: 失敗 | E41: =IF(F41>=2,"◯",IF(F41>0,"△","✕")) -> ◯ | F41: =COUNTIFS(todayssatellite!$E:$E,データチェック!B41,todayssatellite!$F:$F,データチェック!C41) -> 2 | G41: =OFFSET(todayssatellite!$B$1,MATCH(B41&"_"&C41,todayssatellite!$G:$G,0)-1,0) -> 【今日の人工衛星】11/29 2003年：情報収集衛星光学・レーダー2号機(IGS-2A/B) H-IIAロケット6号機で打上たが、SRB-Aの分離失敗によりロケットが指令破壊され喪失。これ以降実証衛星以外の2機同時打上は行われなくなった | I41: J_E | J41: 6 | K41: 失敗 | L41: =IF(M41>=2,"◯",IF(M41>0,"△","✕")) -> ✕ | M41: =COUNTIFS(todayssatellite!$E:$E,データチェック!I41,todayssatellite!$F:$F,データチェック!J41) -> 0 | N41: =OFFSET(todayssatellite!$B$1,MATCH(I41&"_"&J41,todayssatellite!$G:$G,0)-1,0) -> #N/A | P41: n012402t1 | Q41: 1
B42: J_H2A | C42: 7 | E42: =IF(F42>=2,"◯",IF(F42>0,"△","✕")) -> ◯ | F42: =COUNTIFS(todayssatellite!$E:$E,データチェック!B42,todayssatellite!$F:$F,データチェック!C42) -> 2 | G42: =OFFSET(todayssatellite!$B$1,MATCH(B42&"_"&C42,todayssatellite!$G:$G,0)-1,0) -> 【今日の人工衛星】2/26 2005年：MTSAT-1R[ひまわり6号] 運輸多目的衛星新1号、日本時間18:25に打ち上げ。H-IIAが日本の空に蘇った日でもある。これ以降H-IIAは連続して打ち上げ成功している。 | P42: n012501d | Q42: 1
...
